@Test public void throwing(){
  Verify.assertThrowsWithCause(RuntimeException.class,IOException.class,() -> Functions.throwing(a -> {
    throw new IOException();
  }
).valueOf(null));
}
